Workbook

Sheet README
A1: Novčić Pay — pricing model and calculations 2027
A2: Price Management, ZSEM MBA 2026/27 · individual pricing project · case 05 (Case Book p. 7) · model built 02.10.2026, audited and extended 05.10.2026
A4: What this file is
A5: The one place where every number of the project is produced. Type only on the Inputs sheet; every other sheet is live formulas. The website and the dashboard show the same figures (sheet 'Dashboard map').
A7: Read in this order
A8: 1 · KPIs — the 18 measures that judge the price list (definition, formula, result, criterion, met or not, interpretation) and the eight operating KPIs for 2027.
A9: 2 · Inputs — CASE FACTS (blue), ASSUMPTIONS not on the case sheet (orange), DECISIONS = the price list (green).
A10: 3 · Segment economics — contribution per customer per month for each segment under each offer (today, Basic, Plus, Travel).
A11: 4 · Model — the recommended structure: each segment followed through its choices (buys the plan / stays on Basic / leaves), contribution per offer and in total, profit.
A12: 5 · Bridge — from today's loss to the 2027 contribution, line by line.
A13: 6 · Alternatives — the same customers under five structures: everything free, fees per use only, one monthly fee, Basic + Travel only, the recommendation.
A14: 7 · Price grid — contribution of each segment at each surveyed price point.
... A29: The company is fictitious; all case figures were invented for the course.

Sheet KPIs
A1: KPI register — definition, formula, result, criterion, verdict, interpretation, source
A2: Part 1: the KPIs that judge the price list itself (all results are live formulas). Part 2: the eight operating KPIs Novčić would track in 2027 (Balanced Scorecard; Kaplan & Norton 1992). Criteria are the project's own unless marked 'case'.
A4: Part 1 · Does the price list do its job? (model results)
A5: # | B5: Objective | C5: KPI | D5: Definition / formula | E5: Result | F5: Criterion | G5: Met? | H5: Interpretation | I5: Workbook source | J5: Dashboard page
A6: 1 | B6: Pay for itself from 2027 (case) | C6: Profit after fixed costs | D6: Contribution − fixed costs of 700,000 | E6: =reco_profit -> 176182.4 | F6: ≥ 0 (case: the account has to pay for itself) | G6: =IF(E6>=0,"met","NOT MET") -> met | H6: The price list turns a loss of 1.28 million into a profit. This is the base case: the survey taken at face value. | I6: Model | J6: Overview · 3 Numbers
A7: 2 | B7: Pay for itself from 2027 (case) | C7: Contribution per year | D7: Σ income − Σ variable cost, all retained customers × 12 | E7: =reco_total -> 876182.4 | F7: ≥ fixed costs (700,000) | G7: =IF(E7>=fixed,"met","NOT MET") -> met | H7: Plans and per-use fees each deliver about half. | I7: Model | J7: 3 Numbers
A8: 3 | B8: Pay for itself from 2027 (case) | C8: Safety margin | D8: 1 − fixed costs ÷ contribution | E8: =1-fixed/reco_total -> 0.20107959 | F8: ≥ 10% | G8: =IF(E8>=0.1,"met","NOT MET") -> met | H8: Contribution may fall by a fifth before a loss. | I8: Break-even B10 | J8: 3 Numbers
A9: 4 | B9: Pay for itself from 2027 (case) | C9: Break-even customers | D9: Fixed costs ÷ (blended contribution per customer × 12) | E9: ='Break-even'!B9 -> 30231.148 | F9: ≤ customers retained | G9: =IF(E9<=Model!E13,"met","NOT MET") -> met | H9: 30,231 of the 37,840 retained customers are needed at the model's mix. | I9: Break-even B9 | J9: 3 Numbers
A10: 5 | B10: Pay for itself from 2027 (case) | C10: Gain over the best alternative structure | D10: Contribution ÷ highest contribution among A–D − 1 | E10: =reco_total/MAX(Alternatives!E5:E8)-1 -> 0.13720213 | F10: > 0 | G10: =IF(E10>0,"met","NOT MET") -> met | H10: Segmented pricing beats one price (handout 04). The flat fee is compared at the level set on Inputs (3.99). | I10: Alternatives | J10: Overview · 3 Numbers
A11: 6 | B11: Keep the generation | C11: Customers retained | D11: Retained customers ÷ 40,000 | E11: =Model!E13/Inputs!$B$10 -> 0.946 | F11: ≥ retention of per-use fees alone (B) | G11: =IF(E11>=Alternatives!G6/Inputs!$B$10,"met","NOT MET") -> met | H11: The plans do not only add income; they keep 2,200 customers that pure per-use fees would lose (mainly travellers). | I11: Model | J11: Overview
A12: 7 | B12: Keep the generation | C12: Students retained | D12: Students retained ÷ 24,000 | E12: =Model!B13/Inputs!$B$6 -> 0.954 | F12: ≥ 95% | G12: =IF(E12>=0.95,"met","NOT MET") -> met | H12: The pipeline segment stays almost intact; a monthly fee would keep 45%. | I12: Model | J12: 1 Customers
A13: 8 | B13: Charge for what costs us | C13: Cash cost coverage | D13: Withdrawal fee income ÷ cost of all withdrawals (incl. those in plans) | E13: =Model!E33/-Model!E39 -> 1.0134889 | F13: ≥ 100% | G13: =IF(E13>=1,"met","NOT MET") -> met | H13: The largest variable cost is now paid for by those who cause it — with one point to spare, so it is the first ratio to watch. | I13: Model (income and cost rows) | J13: 3 Numbers · KPIs
A14: 9 | B14: Charge for what costs us | C14: Lowest contribution per customer among the segments on Basic | D14: MIN of Basic contribution per month (students, employees, travellers) | E14: =MIN('Segment economics'!C15,'Segment economics'!G15,'Segment economics'!K15) -> 0.7 | F14: > 0 | G14: =IF(E14>0,"met","NOT MET") -> met | H14: Every segment covers its variable cost even without a plan; today none does. | I14: Segment economics | J14: 1 Customers
A15: 10 | B15: Plans customers choose | C15: Plan attach rate | D15: Plus + Travel subscribers ÷ customers retained | E15: =Model!E9/Model!E13 -> 0.25158562 | F15: ≥ 25% | G15: =IF(E15>=0.25,"met","NOT MET") -> met | H15: A quarter of the customers produce half of the contribution. | I15: Model | J15: 3 Numbers · KPIs
A16: 11 | B16: Price inside the value range | C16: Plus: price position | D16: (price − reference value) ÷ (proxy EVC − reference value) | E16: =EVE!B33 -> 0.49748744 | F16: between 0% and 100% | G16: =IF(AND(E16>=0,E16<=1),"met","NOT MET") -> met | H16: Plus captures half of the differentiation value (50:50 starting point, handout 07). | I16: EVE B29:B33 | J16: 2 Pricing
A17: 12 | B17: Price inside the value range | C17: Travel: price minus reference value | D17: Travel price − Fluxa bill for the same usage | E17: =EVE!B14 -> -1.01 | F17: reference value ≤ price ≤ EVC (value-based range) | G17: =IF(AND(EVE!B12>=EVE!B6,EVE!B12<=EVE!B9),"met","NOT MET") -> NOT MET | H17: NOT MET ON PURPOSE: 6.99 is below the value-based floor of 8.00 (penetration price). It is the contribution-maximising surveyed price and keeps 70% of the segment; stated willingness to pay centres on the reference value. Above the cost floor of 2.70. 7.99 is the price to test. | I17: EVE B6:B16 | J17: 2 Pricing
A18: 13 | B18: Price level holds | C18: Neighbouring surveyed prices that would raise total profit | D18: Count of 4 moves (Plus 2.99, Plus 4.99, Travel 5.99, Travel 8.99; Plus has one price for students and employees) with a higher profit than the price list | E18: =(Sensitivity!AG27>reco_profit)+(Sensitivity!AG23>reco_profit)+(Sensitivity!AG21>reco_profit)+(Sensitivity!AG24>reco_profit) -> 0 | F18: =0 -> 0 | G18: =IF(E18=0,"met","NOT MET") -> met | H18: No neighbouring surveyed price earns more in total. Closest: Travel 8.99 (−14,400) and Plus 4.99 (−19,700). For students alone 2.99 would pay (+7,700), but the employees lose 56,500 at that price. | I18: Sensitivity · Break-even rows 39–58 | J18: 2 Pricing · 3 Numbers
A19: 14 | B19: Structure fits the segments | C19: Self-selection holds | D19: Travel is the cheapest offer for travellers AND Plus is not cheaper than Basic for the typical employee | E19: =IF(AND(Arbitrage!E7="Travel",Arbitrage!C6>Arbitrage!B6),1,0) -> 1 | F19: =1 -> 1 | G19: =IF(E19=1,"met","NOT MET") -> met | H19: Travellers gain by choosing Travel; employees buy Plus for its features, not to avoid fees (no cannibalisation). | I19: Arbitrage | J19: 2 Pricing
A20: 15 | B20: Robust, not only optimal | C20: Probability of at least breaking even under joint uncertainty | D20: Share of 5,000 simulated draws with profit ≥ 0 | E20: =1-'Stress test'!H40 -> 0.8618 | F20: ≥ 80% and above every alternative | G20: =IF(AND(E20>=0.8,'Stress test'!H40<MIN('Stress test'!H41:H43)),"met","NOT MET") -> met | H20: The recommendation is the only structure that breaks even in most draws (one fee: about 30%). | I20: Stress test, block C | J20: Risk
A21: 16 | B21: Robust, not only optimal | C21: Median profit under joint uncertainty | D21: Median of 5,000 draws | E21: ='Stress test'!E40 -> 52915.517 | F21: > 0 | G21: =IF(E21>0,"met","NOT MET") -> met | H21: The honest expectation is about a third of the base case: the base case is close to the best case. | I21: Stress test, block C | J21: Overview · Risk
A22: 17 | B22: Robust, not only optimal | C22: Withdrawals Basic customers may avoid before a loss | D22: Switching value of the withdrawal reduction | E22: ='Stress test'!F6 -> 0.8233438 | F22: ≥ 50% | G22: =IF(E22>=0.5,"met","NOT MET") -> met | H22: Withdrawals would have to fall by more than four fifths. | I22: Stress test, block A | J22: Risk
A23: 18 | B23: Robust, not only optimal | C23: Profit in the combined downside scenario | D23: 50% fewer withdrawals, take-up −20%, features 0.25 | E23: =Sensitivity!AG26 -> 6245.12 | F23: ≥ 0 | G23: =IF(E23>=0,"met","NOT MET") -> met | H23: Three adverse moves at once still leave break-even. | I23: Sensitivity | J23: Risk
C24: KPIs met | E24: =COUNTIF(G6:G23,"met") -> 17 | F24: of 18
A26: Part 2 · Operating scorecard 2027: what Novčić measures from the first month (targets follow from the model; none can be 'met' before launch)
A27: # | B27: Perspective · objective | C27: Measure | D27: Definition | E27: Model baseline | F27: Target | G27: Lead / lag | H27: Why this KPI, and what triggers a review | I27: Data source | J27: Dashboard page
A28: 1 | B28: Financial · pay for itself | C28: Contribution per active customer per month | D28: Contribution ÷ active customers ÷ 12 | E28: ='Break-even'!B8 -> 1.9295772 | F28: ≥ 1.93 (break-even at 30,231 customers) | G28: lag | H28: One number that says whether the price list works; profit alone would hide a shrinking base. | I28: Novčić account data (from January 2027) | J28: KPIs and roll-out
A29: 2 | B29: Financial · charge for what costs us | C29: Cash cost coverage | D29: Withdrawal fee income ÷ withdrawal cost | E29: =Model!E33/-Model!E39 -> 1.0134889 | F29: ≥ 100% | G29: lead | H29: Moves months before profit does. Below 100% for a quarter → review the withdrawal fee. | I29: Novčić account data (from January 2027) | J29: KPIs and roll-out
A30: 3 | B30: Customer · keep the generation | C30: Customers retained after the price list | D30: Active customers ÷ 40,000 | E30: =Model!E13/Inputs!$B$10 -> 0.946 | F30: ≥ 94%; students ≥ 95% | G30: lag | H30: The reason for the €0 account. A monthly fee would have cut this to 58.5%. | I30: Novčić account data (from January 2027) | J30: KPIs and roll-out
A31: 4 | B31: Customer · plans customers choose | C31: Plan attach rate | D31: Subscribers ÷ active customers; Travel take-up among travellers | E31: =Model!E9/Model!E13 -> 0.25158562 | F31: ≥ 25%; Travel ≥ 70% of travellers | G31: lead | H31: Demand-side test of the value message. Travel take-up above 80% for two quarters → test 7.99. | I31: Novčić account data (from January 2027) | J31: KPIs and roll-out
A32: 5 | B32: Internal process · be the transparent one | C32: Mark-up shown before payment; fee complaints | D32: Share of currency payments with the ECB mark-up shown before confirmation; complaints per 1,000 customers | E32: n/a | F32: 100% · < 2 per 1,000 | G32: lead | H32: A legal constraint and the fairness lever (handout 05). | I32: Novčić account data (from January 2027) | J32: KPIs and roll-out
A33: 6 | B33: Internal process · keep cash use economic | C33: Withdrawals per Basic customer per month | D33: Withdrawals ÷ Basic customers | E33: =(Model!B12*Inputs!$E$6+Model!C12*Inputs!$E$7+Model!D12*Inputs!$E$8)/Model!E12 -> 1.259322 | F33: track; review below 0.9 | G33: lead | H33: Turns the biggest model uncertainty into a measured number (profit is zero at −82%). | I33: Novčić account data (from January 2027) | J33: KPIs and roll-out
A34: 7 | B34: Learning and growth · explain the price list | C34: Support staff certified on the fee information document | D34: Certified ÷ support staff | E34: n/a | F34: 100% before launch | G34: lead | H34: The fee document and the ECB rule are only as good as the people who explain them. | I34: Novčić account data (from January 2027) | J34: KPIs and roll-out
A35: 8 | B35: Learning and growth · price with evidence | C35: Monthly take-up and churn report by segment, with a named owner | D35: Report live yes/no; quarterly price review held | E35: n/a | F35: live in Q1 2027 | G35: lead | H35: The model's assumptions must be replaced by observed data within one quarter. | I35: Novčić account data (from January 2027) | J35: KPIs and roll-out

Sheet Inputs
A1: Inputs — case facts, assumptions, decisions
A2: Blue = fact from the case sheet · orange = assumption (not on the sheet) · green = decision. Only these cells are typed in; everything else is a formula.
A4: CASE FACTS — customers and what they told us (survey of 2,000 customers)
A5: Segment | B5: Customers | C5: Card payments / month | D5: of which other currencies | E5: Cash withdrawals / month | F5: Leave if the account itself has a monthly fee | G5: Leave if per-use fees (of those who pay them) | H5: Plan price 1 | I5: Share 1 | J5: Plan price 2 | K5: Share 2 | L5: Plan price 3 | M5: Share 3
A6: Students (18–22) | B6: 24000 | C6: 250 | D6: 25 | E6: 1 | F6: 0.55 | G6: 0.05 | H6: 2.99 | I6: 0.15 | J6: 3.99 | K6: 0.08 | L6: 4.99 | M6: 0.04
A7: Young employees (23–26) | B7: 12000 | C7: 900 | D7: 50 | E7: 2 | F7: 0.25 | G7: 0.03 | H7: 2.99 | I7: 0.5 | J7: 3.99 | K7: 0.4 | L7: 4.99 | M7: 0.2
A8: Travellers | B8: 4000 | C8: 800 | D8: 400 | E8: 2 | F8: 0.1 | G8: 0.7 | H8: 5.99 | I8: 0.8 | J8: 6.99 | K8: 0.7 | L8: 8.99 | M8: 0.3
A9: Plan asked about: students and employees — free cash withdrawals, shared accounts, virtual cards. Travellers — no currency fee, free withdrawals worldwide, travel insurance.
A10: Total customers | B10: =SUM(B6:B8) -> 40000
A12: CASE FACTS — income and costs
A13: Income from merchants' banks: share of all card payments (EU limit for debit cards) | B13: 0.002
A14: Cost per customer per month (card, processing, checks, support) | B14: 0.6
A15: Cost per cash withdrawal | B15: 1
A16: Cost of payments in other currencies (share of amount) | B16: 0.003
A17: Travel insurance per insured customer per month | B17: 0.5
A18: Fixed costs per year (licence, compliance, IT, staff) | B18: 700000
A20: CASE FACTS — survey fee scenario and competitors
A21: Survey scenario: fee per cash withdrawal | B21: 1.5
A22: Survey scenario: fee on other currencies, above the ECB rate | B22: 0.015
A23: Fluxa: fee on other currencies | B23: 0.01
A24: Fluxa: fee per withdrawal abroad | B24: 2
A25: Fluxa Premium per month (no currency fee) | B25: 9.99
A26: Travel insurance bought separately, per month (about) | B26: 4
A27: Banks: fee on other currencies | B27: 0.025
A28: Banks: fee per withdrawal, low / high | B28: 1 | C28: 2
A29: Banks: account package per month, low / high | B29: 3 | C29: 5
A31: ASSUMPTIONS — not on the case sheet (each one is tested on the Sensitivity sheet)
A32: Extra cost of Plus features (shared accounts, virtual cards) per subscriber per month | B32: 0 | C32: Software features; marginal cost close to zero. 0.25 and 0.50 tested.
A33: Share of withdrawals that Basic customers stop making once a withdrawal costs 1.50 | B33: 0 | C33: The case says nothing about behaviour; each avoided withdrawal costs Novčić 0.50 of margin. 25–75% tested.
A34: Withdrawals of a Plus subscriber relative to the segment average (1 = unchanged) | B34: 1 | C34: Withdrawals are included in Plus up to the cap below; the cap keeps this near 1. 1.5 and 2 tested.
A35: Plus: withdrawals included per month (cap, then the Basic fee applies) | B35: 3 | C35: Covers the typical employee (2) and student (1); protects against heavy cash users (handout 04).
A36: Per-use churn applies only to customers who actually pay the per-use fees (plan buyers do not leave) | B36: 1 | C36: Reading of the sheet: '… of the students/employees/travellers who pay these fees would leave'.
A37: Plan buyers: survey share at the chosen price buys; the rest stay on Basic (then the per-use churn applies) | B37: 1 | C37: Customers who do not buy a plan still do something: stay on Basic, or leave.
A39: DECISIONS — the price list (change these)
A40: Basic: fee per cash withdrawal | B40: 1.5 | C40: Survey level. Cost 1.00 → margin 0.50 per withdrawal. Fluxa charges 2.00 abroad, banks 1–2.
A41: Basic: fee on other currencies above the ECB rate | B41: 0.015 | C41: Survey level. Cost 0.3%. Fluxa 1.0%, banks 2.5%.
A42: Plus price per month — students (needs student verification if different) | B42: 3.99 | C42: Set equal to pE for one Plus price; 2.99 with a student fence adds about 7,700 a year.
A43: Plus price per month — young employees | B43: 3.99 | C43: Only 2.99 / 3.99 / 4.99 have survey shares.
A44: Travel price per month | B44: 6.99 | C44: Only 5.99 / 6.99 / 8.99 have survey shares.
A45: Alternative for comparison: one monthly fee for everyone (everything included) | B45: 3.99 | C45: Bank package range is 3–5.
...

Sheet Segment economics
A1: Contribution per customer per month, by segment and offer
A2: Income − variable cost for one typical member of the segment (usage as on the case sheet). A plan price is counted as income; services included in a plan show their cost but no fee income.
A4: Segment | B4: Students | C4: Students | D4: Students | E4: Students | F4: Employees | G4: Employees | H4: Employees | I4: Employees | J4: Travellers | K4: Travellers | L4: Travellers | M4: Travellers
A5: Offer | B5: Today (all free) | C5: Basic | D5: Plus | E5: Travel | F5: Today (all free) | G5: Basic | H5: Plus | I5: Travel | J5: Today (all free) | K5: Basic | L5: Plus | M5: Travel
A6: Card payments (interchange) | B6: =ic*Inputs!$C$6 -> 0.5 | C6: =ic*Inputs!$C$6 -> 0.5 | D6: =ic*Inputs!$C$6 -> 0.5 | E6: =ic*Inputs!$C$6 -> 0.5 | F6: =ic*Inputs!$C$7 -> 1.8 | G6: =ic*Inputs!$C$7 -> 1.8 | H6: =ic*Inputs!$C$7 -> 1.8 | I6: =ic*Inputs!$C$7 -> 1.8 | J6: =ic*Inputs!$C$8 -> 1.6 | K6: =ic*Inputs!$C$8 -> 1.6 | L6: =ic*Inputs!$C$8 -> 1.6 | M6: =ic*Inputs!$C$8 -> 1.6
A7: Plan fee | B7: 0 | C7: 0 | D7: =pS -> 3.99 | E7: =pT -> 6.99 | F7: 0 | G7: 0 | H7: =pE -> 3.99 | I7: =pT -> 6.99 | J7: 0 | K7: 0 | L7: =pE -> 3.99 | M7: =pT -> 6.99
A8: Cash withdrawal fees | B8: 0 | C8: =fee_wd*Inputs!$E$6*(1-wd_red) -> 1.5 | D8: 0 | E8: 0 | F8: 0 | G8: =fee_wd*Inputs!$E$7*(1-wd_red) -> 3 | H8: 0 | I8: 0 | J8: 0 | K8: =fee_wd*Inputs!$E$8*(1-wd_red) -> 3 | L8: 0 | M8: 0
A9: Currency fees | B9: 0 | C9: =fee_fx*Inputs!$D$6 -> 0.375 | D9: =fee_fx*Inputs!$D$6 -> 0.375 | E9: 0 | F9: 0 | G9: =fee_fx*Inputs!$D$7 -> 0.75 | H9: =fee_fx*Inputs!$D$7 -> 0.75 | I9: 0 | J9: 0 | K9: =fee_fx*Inputs!$D$8 -> 6 | L9: =fee_fx*Inputs!$D$8 -> 6 | M9: 0
A10: Account cost | B10: =-cost_acc -> -0.6 | C10: =-cost_acc -> -0.6 | D10: =-cost_acc -> -0.6 | E10: =-cost_acc -> -0.6 | F10: =-cost_acc -> -0.6 | G10: =-cost_acc -> -0.6 | H10: =-cost_acc -> -0.6 | I10: =-cost_acc -> -0.6 | ... M10: =-cost_acc -> -0.6
A11: Cash withdrawal cost | B11: =-cost_wd*Inputs!$E$6 -> -1 | C11: =-cost_wd*Inputs!$E$6*(1-wd_red) -> -1 | D11: =-cost_wd*Inputs!$E$6*plus_wdf -> -1 | E11: =-cost_wd*Inputs!$E$6 -> -1 | F11: =-cost_wd*Inputs!$E$7 -> -2 | G11: =-cost_wd*Inputs!$E$7*(1-wd_red) -> -2 | H11: =-cost_wd*Inputs!$E$7*plus_wdf -> -2 | I11: =-cost_wd*Inputs!$E$7 -> -2 | J11: =-cost_wd*Inputs!$E$8 -> -2 | K11: =-cost_wd*Inputs!$E$8*(1-wd_red) -> -2 | L11: =-cost_wd*Inputs!$E$8*plus_wdf -> -2 | M11: =-cost_wd*Inputs!$E$8 -> -2
A12: Currency cost | B12: =-cost_fx*Inputs!$D$6 -> -0.075 | C12: =-cost_fx*Inputs!$D$6 -> -0.075 | D12: =-cost_fx*Inputs!$D$6 -> -0.075 | E12: =-cost_fx*Inputs!$D$6 -> -0.075 | F12: =-cost_fx*Inputs!$D$7 -> -0.15 | G12: =-cost_fx*Inputs!$D$7 -> -0.15 | H12: =-cost_fx*Inputs!$D$7 -> -0.15 | I12: =-cost_fx*Inputs!$D$7 -> -0.15 | J12: =-cost_fx*Inputs!$D$8 -> -1.2 | K12: =-cost_fx*Inputs!$D$8 -> -1.2 | L12: =-cost_fx*Inputs!$D$8 -> -1.2 | M12: =-cost_fx*Inputs!$D$8 -> -1.2
A13: Insurance cost | B13: 0 | C13: 0 | D13: 0 | E13: =-cost_ins -> -0.5 | F13: 0 | G13: 0 | H13: 0 | I13: =-cost_ins -> -0.5 | J13: 0 | K13: 0 | L13: 0 | M13: =-cost_ins -> -0.5
A14: Plus feature cost | B14: 0 | C14: 0 | D14: =-feat_cost -> 0 | E14: 0 | F14: 0 | G14: 0 | H14: =-feat_cost -> 0 | I14: 0 | J14: 0 | K14: 0 | L14: =-feat_cost -> 0 | M14: 0
A15: Contribution per month | B15: =SUM(B6:B14) -> -1.175 | C15: =SUM(C6:C14) -> 0.7 | D15: =SUM(D6:D14) -> 3.19 | E15: =SUM(E6:E14) -> 5.315 | F15: =SUM(F6:F14) -> -0.95 | G15: =SUM(G6:G14) -> 2.8 | H15: =SUM(H6:H14) -> 3.79 | I15: =SUM(I6:I14) -> 5.54 | ... M15: =SUM(M6:M14) -> 4.29
A16: Contribution per year | B16: =B15*12 -> -14.1 | C16: =C15*12 -> 8.4 | D16: =D15*12 -> 38.28 | E16: =E15*12 -> 63.78 | F16: =F15*12 -> -11.4 | G16: =G15*12 -> 33.6 | H16: =H15*12 -> 45.48 | I16: =I15*12 -> 66.48 | ... M16: =M15*12 -> 51.48
A18: Reading: today every segment loses money; the cash withdrawal (cost 1.00, no fee) is the largest single leak. Basic turns each segment positive through per-use fees; Plus and Travel earn more per subscriber than Basic for employees and travellers, but a plan is worth offering only if its take-up × margin beats what the same customers would pay per use (see Model and Price grid).

Sheet Model
A1: Recommended structure — each segment followed through its choices (2027, per year)
A2: Basic account (no monthly fee, fees per use) for everyone · Plus for students and employees · Travel for travellers. Non-buyers stay on Basic or leave (survey churn).
B4: Students | C4: Employees | D4: Travellers | E4: Total
A5: Customers today | B5: =Inputs!$B$6 -> 24000 | C5: =Inputs!$B$7 -> 12000 | D5: =Inputs!$B$8 -> 4000 | E5: =SUM(B5:D5) -> 40000
A6: Plan offered | B6: Plus | C6: Plus | D6: Travel
A7: Plan price per month | B7: =pS -> 3.99 | C7: =pE -> 3.99 | D7: =pT -> 6.99
A8: Share who buy the plan (survey) | B8: =IF(pS="",0,MIN(1,1*IF(pS=Inputs!$H$6,Inputs!$I$6,IF(pS=Inputs!$J$6,Inputs!$K$6,IF(pS=Inputs!$L$6,Inputs!$M$6,NA()))))) -> 0.08 | C8: =IF(pE="",0,MIN(1,1*IF(pE=Inputs!$H$7,Inputs!$I$7,IF(pE=Inputs!$J$7,Inputs!$K$7,IF(pE=Inputs!$L$7,Inputs!$M$7,NA()))))) -> 0.4 | D8: =IF(pT="",0,MIN(1,1*IF(pT=Inputs!$H$8,Inputs!$I$8,IF(pT=Inputs!$J$8,Inputs!$K$8,IF(pT=Inputs!$L$8,Inputs!$M$8,NA()))))) -> 0.7
A9: Plan subscribers | B9: =B5*B8 -> 1920 | C9: =C5*C8 -> 4800 | D9: =D5*D8 -> 2800 | E9: =SUM(B9:D9) -> 9520
A10: Do not buy the plan | B10: =B5-B9 -> 22080 | C10: =C5-C9 -> 7200 | D10: =D5-D9 -> 1200 | E10: =SUM(B10:D10) -> 30480
A11: … of whom leave (per-use churn) | B11: =B10*Inputs!$G$6*churn_nonbuyers -> 1104 | C11: =C10*Inputs!$G$7*churn_nonbuyers -> 216 | D11: =D10*Inputs!$G$8*churn_nonbuyers -> 840 | E11: =SUM(B11:D11) -> 2160
A12: … of whom stay on Basic | B12: =B10-B11 -> 20976 | C12: =C10-C11 -> 6984 | D12: =D10-D11 -> 360 | E12: =SUM(B12:D12) -> 28320
A13: Customers retained | B13: =B9+B12 -> 22896 | C13: =C9+C12 -> 11784 | D13: =D9+D12 -> 3160 | E13: =SUM(B13:D13) -> 37840
A14: Contribution per plan subscriber per month | B14: ='Segment economics'!D15 -> 3.19 | C14: ='Segment economics'!H15 -> 3.79 | D14: ='Segment economics'!M15 -> 4.29
A15: Contribution per Basic customer per month | B15: ='Segment economics'!C15 -> 0.7 | C15: ='Segment economics'!G15 -> 2.8 | D15: ='Segment economics'!K15 -> 6.8
A16: Contribution from the plan per year | B16: =12*B9*B14 -> 73497.6 | C16: =12*C9*C14 -> 218304 | D16: =12*D9*D14 -> 144144 | E16: =SUM(B16:D16) -> 435945.6
A17: Contribution from Basic per year | B17: =12*B12*B15 -> 176198.4 | C17: =12*C12*C15 -> 234662.4 | D17: =12*D12*D15 -> 29376 | E17: =SUM(B17:D17) -> 440236.8
A18: Contribution per year | B18: =B16+B17 -> 249696 | C18: =C16+C17 -> 452966.4 | D18: =D16+D17 -> 173520 | E18: =SUM(B18:D18) -> 876182.4
A20: Total contribution per year | E20: =E18 -> 876182.4
A21: Fixed costs per year | E21: =-fixed -> -700000
A22: Profit per year | E22: =E20+E21 -> 176182.4
A23: Customers retained (share of 40,000) | E23: =E13/Inputs!$B$10 -> 0.946
A24: Customers lost | E24: =E11 -> 2160
A25: Blended contribution per retained customer per month | E25: =E20/E13/12 -> 1.9295772
A26: Break-even: customers needed at this blend | E26: =fixed/E25/12 -> 30231.148
A27: Safety margin: contribution may fall by … before a loss | E27: =1-fixed/E20 -> 0.20107959
A29: Where the money comes from and goes (per year, recommended structure)
A30: Income
A31: Interchange (0.2% of card payments) | B31: =12*(B9+B12)*ic*Inputs!$C$6 -> 137376 | C31: =12*(C9+C12)*ic*Inputs!$C$7 -> 254534.4 | D31: =12*(D9+D12)*ic*Inputs!$C$8 -> 60672 | E31: =SUM(B31:D31) -> 452582.4
A32: Plan fees (Plus + Travel) | B32: =12*B9*pS -> 91929.6 | C32: =12*C9*pE -> 229824 | D32: =12*D9*pT -> 234864 | E32: =SUM(B32:D32) -> 556617.6
A33: Cash withdrawal fees (Basic) | B33: =12*B12*fee_wd*Inputs!$E$6*(1-wd_red) -> 377568 | C33: =12*C12*fee_wd*Inputs!$E$7*(1-wd_red) -> 251424 | D33: =12*D12*fee_wd*Inputs!$E$8*(1-wd_red) -> 12960 | E33: =SUM(B33:D33) -> 641952
A34: Currency fees (Basic + Plus) | B34: =12*(B12+B9)*fee_fx*Inputs!$D$6 -> 103032 | C34: =12*(C12+C9)*fee_fx*Inputs!$D$7 -> 106056 | D34: =12*(D12)*fee_fx*Inputs!$D$8 -> 25920 | E34: =SUM(B34:D34) -> 235008
A35: Total income | B35: =SUM(B31:B34) -> 709905.6 | C35: =SUM(C31:C34) -> 841838.4 | D35: =SUM(D31:D34) -> 334416 | E35: =SUM(E31:E34) -> 1886160
A37: Variable costs
A38: Account cost | B38: =-12*(B9+B12)*cost_acc -> -164851.2 | C38: =-12*(C9+C12)*cost_acc -> -84844.8 | D38: =-12*(D9+D12)*cost_acc -> -22752 | E38: =SUM(B38:D38) -> -272448
A39: Cash withdrawal cost | B39: =-12*cost_wd*Inputs!$E$6*(B12*(1-wd_red)+B9*plus_wdf) -> -274752 | C39: =-12*cost_wd*Inputs!$E$7*(C12*(1-wd_red)+C9*plus_wdf) -> -282816 | D39: =-12*cost_wd*Inputs!$E$8*(D12*(1-wd_red)+D9) -> -75840 | E39: =SUM(B39:D39) -> -633408
A40: Currency cost | B40: =-12*(B9+B12)*cost_fx*Inputs!$D$6 -> -20606.4 | C40: =-12*(C9+C12)*cost_fx*Inputs!$D$7 -> -21211.2 | D40: =-12*(D9+D12)*cost_fx*Inputs!$D$8 -> -45504 | E40: =SUM(B40:D40) -> -87321.6
A41: Insurance (Travel) | B41: 0 | C41: 0 | D41: =-12*D9*cost_ins -> -16800 | E41: =SUM(B41:D41) -> -16800
A42: Plus feature cost | B42: =-12*B9*feat_cost -> 0 | C42: =-12*C9*feat_cost -> 0 | D42: 0 | E42: =SUM(B42:D42) -> 0
A43: Total variable costs | B43: =SUM(B38:B42) -> -460209.6 | C43: =SUM(C38:C42) -> -388872 | D43: =SUM(D38:D42) -> -160896 | E43: =SUM(E38:E42) -> -1009977.6
A44: Contribution (check = row above) | B44: =B35+B43 -> 249696 | C44: =C35+C43 -> 452966.4 | D44: =D35+D43 -> 173520 | E44: =E35+E43 -> 876182.4
...

Sheet Bridge
A1: From today's loss to the 2027 contribution — line by line (per year)
A2: Each line is the change the price list causes. The sum reproduces the Model total; the last line checks it.
A4: Step | B4: Change | C4: Running total | D4: Where it comes from
A5: Today: everything free (contribution) | B5: =Alternatives!E5 -> -580800 | C5: =SUM(B$5:B5) -> -580800 | D5: Alternatives, row A. Interchange 480,000 − variable costs 1,060,800.
A6: + Cash withdrawal fees (Basic) | B6: =Model!E33 -> 641952 | C6: =SUM(B$5:B6) -> 61152 | D6: 1.50 × withdrawals of customers on Basic.
A7: + Currency fees (Basic and Plus) | B7: =Model!E34 -> 235008 | C7: =SUM(B$5:B7) -> 296160 | D7: 1.5% above ECB × payments in other currencies.
A8: + Plan fees (Plus and Travel) | B8: =Model!E32 -> 556617.6 | C8: =SUM(B$5:B8) -> 852777.6 | D8: 9,520 subscribers at 3.99 / 6.99.
A9: − Travel insurance for subscribers | B9: =Model!E41 -> -16800 | C9: =SUM(B$5:B9) -> 835977.6 | D9: 0.50 × Travel subscribers.
A10: + Customers who leave no longer cause a loss | B10: =-12*(Model!B11*'Segment economics'!B15+Model!C11*'Segment economics'!F15+Model!D11*'Segment economics'!J15) -> 40204.8 | C10: =SUM(B$5:B10) -> 876182.4 | D10: Each leaver had a negative contribution today (−1.18 / −0.95 / −2.20 a month).
A11: ± Behaviour assumptions (0 at default inputs: withdrawals avoided, Plus use, feature cost) | B11: =reco_total-SUM(B5:B10) -> 0 | C11: =SUM(B$5:B11) -> 876182.4
A12: → Contribution 2027, recommended price list | B12: =reco_total -> 876182.4
A13: − Fixed costs | B13: =-fixed -> -700000
A14: → Profit 2027 | B14: =B12+B13 -> 176182.4
A15: Profit today (contribution − fixed costs) | B15: =B5-fixed -> -1280800
A16: Swing in profit | B16: =B14-B15 -> 1456982.4
A18: Reading: the withdrawal fee alone closes the gap to zero contribution; currency and plan fees then build the 876,000. Half of the swing comes from charging for a service that costs 1.00 each time and was given away 56,000 times a month.

Sheet Alternatives
A1: The same 40,000 customers under five price structures (per year)
A2: Survey responses are applied as on the case sheet. The flat fee uses the churn for 'a monthly fee on the account itself'; that share was not asked per fee level, so the flat-fee result is only credible in the bank-package range (3–5) — see note.
A4: Structure | B4: Students | C4: Employees | D4: Travellers | E4: Contribution | F4: Profit after fixed | G4: Customers retained
A5: A · Today: everything free | B5: =12*Inputs!$B$6*(ic*Inputs!$C$6-cost_acc-cost_wd*Inputs!$E$6-cost_fx*Inputs!$D$6) -> -338400 | C5: =12*Inputs!$B$7*(ic*Inputs!$C$7-cost_acc-cost_wd*Inputs!$E$7-cost_fx*Inputs!$D$7) -> -136800 | D5: =12*Inputs!$B$8*(ic*Inputs!$C$8-cost_acc-cost_wd*Inputs!$E$8-cost_fx*Inputs!$D$8) -> -105600 | E5: =SUM(B5:D5) -> -580800 | F5: =E5-fixed -> -1280800 | G5: =Inputs!$B$10 -> 40000
A6: B · Fees per use only (1.50 per withdrawal, 1.5% above ECB), no plans | B6: =12*Inputs!$B$6*(1-Inputs!$G$6)*(ic*Inputs!$C$6+fee_wd*Inputs!$E$6*(1-wd_red)+fee_fx*Inputs!$D$6-cost_acc-cost_wd*Inputs!$E$6*(1-wd_red)-cost_fx*Inputs!$D$6) -> 191520 | C6: =12*Inputs!$B$7*(1-Inputs!$G$7)*(ic*Inputs!$C$7+fee_wd*Inputs!$E$7*(1-wd_red)+fee_fx*Inputs!$D$7-cost_acc-cost_wd*Inputs!$E$7*(1-wd_red)-cost_fx*Inputs!$D$7) -> 391104 | D6: =12*Inputs!$B$8*(1-Inputs!$G$8)*(ic*Inputs!$C$8+fee_wd*Inputs!$E$8*(1-wd_red)+fee_fx*Inputs!$D$8-cost_acc-cost_wd*Inputs!$E$8*(1-wd_red)-cost_fx*Inputs!$D$8) -> 97920 | E6: =SUM(B6:D6) -> 680544 | F6: =E6-fixed -> -19456 | G6: =Inputs!$B$6*(1-Inputs!$G$6)+Inputs!$B$7*(1-Inputs!$G$7)+Inputs!$B$8*(1-Inputs!$G$8) -> 35640
A7: C · One monthly fee for everyone, everything included (fee on Inputs) | B7: =12*Inputs!$B$6*(1-Inputs!$F$6)*(ic*Inputs!$C$6+flat_fee-cost_acc-cost_wd*Inputs!$E$6-cost_fx*Inputs!$D$6) -> 364824 | C7: =12*Inputs!$B$7*(1-Inputs!$F$7)*(ic*Inputs!$C$7+flat_fee-cost_acc-cost_wd*Inputs!$E$7-cost_fx*Inputs!$D$7) -> 328320 | D7: =12*Inputs!$B$8*(1-Inputs!$F$8)*(ic*Inputs!$C$8+flat_fee-cost_acc-cost_wd*Inputs!$E$8-cost_fx*Inputs!$D$8) -> 77328 | E7: =SUM(B7:D7) -> 770472 | F7: =E7-fixed -> 70472 | G7: =Inputs!$B$6*(1-Inputs!$F$6)+Inputs!$B$7*(1-Inputs!$F$7)+Inputs!$B$8*(1-Inputs!$F$8) -> 23400
A8: D · Basic + Travel only (no Plus plan) | B8: =12*Inputs!$B$6*(1-Inputs!$G$6)*(ic*Inputs!$C$6+fee_wd*Inputs!$E$6*(1-wd_red)+fee_fx*Inputs!$D$6-cost_acc-cost_wd*Inputs!$E$6*(1-wd_red)-cost_fx*Inputs!$D$6) -> 191520 | C8: =12*Inputs!$B$7*(1-Inputs!$G$7)*(ic*Inputs!$C$7+fee_wd*Inputs!$E$7*(1-wd_red)+fee_fx*Inputs!$D$7-cost_acc-cost_wd*Inputs!$E$7*(1-wd_red)-cost_fx*Inputs!$D$7) -> 391104 | D8: =Model!D18 -> 173520 | E8: =SUM(B8:D8) -> 756144 | F8: =E8-fixed -> 56144 | G8: =Inputs!$B$6*(1-Inputs!$G$6)+Inputs!$B$7*(1-Inputs!$G$7)+Model!D13 -> 37600
A9: E · Recommended: Basic + Plus + Travel (prices on Inputs) | B9: =Model!B18 -> 249696 | C9: =Model!C18 -> 452966.4 | D9: =Model!D18 -> 173520 | E9: =SUM(B9:D9) -> 876182.4 | F9: =E9-fixed -> 176182.4 | G9: =Model!E13 -> 37840
A11: Gain of the recommendation (handout 04, formula 1: contribution ÷ contribution of the alternative − 1)
A12: vs B · fees per use only | E12: =E9-E6 -> 195638.4 | F12: =E9/E6-1 -> 0.28747355
A13: vs C · one monthly fee | E13: =E9-E7 -> 105710.4 | F13: =E9/E7-1 -> 0.13720213
A14: vs D · Basic + Travel only | E14: =E9-E8 -> 120038.4 | F14: =E9/E8-1 -> 0.15875071
A16: One monthly fee at each level (same churn at every level — the survey gave no level):
A17: Flat fee 2.99 | B17: 2.99 | E17: =12*Inputs!$B$6*(1-Inputs!$F$6)*(ic*Inputs!$C$6+B17-cost_acc-cost_wd*Inputs!$E$6-cost_fx*Inputs!$D$6)+12*Inputs!$B$7*(1-Inputs!$F$7)*(ic*Inputs!$C$7+B17-cost_acc-cost_wd*Inputs!$E$7-cost_fx*Inputs!$D$7)+12*Inputs!$B$8*(1-Inputs!$F$8)*(ic*Inputs!$C$8+B17-cost_acc-cost_wd*Inputs!$E$8-cost_fx*Inputs!$D$8) -> 489672 | F17: =E17-fixed -> -210328
A18: Flat fee 3.99 | B18: 3.99 | E18: =12*Inputs!$B$6*(1-Inputs!$F$6)*(ic*Inputs!$C$6+B18-cost_acc-cost_wd*Inputs!$E$6-cost_fx*Inputs!$D$6)+12*Inputs!$B$7*(1-Inputs!$F$7)*(ic*Inputs!$C$7+B18-cost_acc-cost_wd*Inputs!$E$7-cost_fx*Inputs!$D$7)+12*Inputs!$B$8*(1-Inputs!$F$8)*(ic*Inputs!$C$8+B18-cost_acc-cost_wd*Inputs!$E$8-cost_fx*Inputs!$D$8) -> 770472 | F18: =E18-fixed -> 70472
A19: Flat fee 4.99 | B19: 4.99 | E19: =12*Inputs!$B$6*(1-Inputs!$F$6)*(ic*Inputs!$C$6+B19-cost_acc-cost_wd*Inputs!$E$6-cost_fx*Inputs!$D$6)+12*Inputs!$B$7*(1-Inputs!$F$7)*(ic*Inputs!$C$7+B19-cost_acc-cost_wd*Inputs!$E$7-cost_fx*Inputs!$D$7)+12*Inputs!$B$8*(1-Inputs!$F$8)*(ic*Inputs!$C$8+B19-cost_acc-cost_wd*Inputs!$E$8-cost_fx*Inputs!$D$8) -> 1051272 | F19: =E19-fixed -> 351272
A21: Note: at 4.99 the flat fee looks best only because the survey churn (55 / 25 / 10%) is held constant. The plan ladder says only 4% of students and 20% of employees would pay 4.99 even for a plan with extra features, so retaining 45% of students at a 4.99 mandatory fee is not credible. The honest comparison is at 2.99–3.99; even there the flat fee loses 41% of the customers (16,600) against 5% in the recommendation.

Sheet Price grid
A1: Contribution of each segment at each surveyed price point (per year)
A2: Segments are independent in the model, so the best price can be chosen segment by segment. 'No plan' = everyone on Basic.
A4: Segment / price | B4: Price | C4: Take-up | D4: Subscribers | E4: Stay on Basic | F4: Leave | G4: Plan contribution | H4: Basic contribution | I4: Total | J4: Best?
A5: Students
A6: No plan | C6: 0 | D6: 0 | E6: =Inputs!$B$6*(1-Inputs!$G$6) -> 22800 | F6: =Inputs!$B$6*Inputs!$G$6 -> 1200 | G6: 0 | H6: =12*E6*(ic*Inputs!$C$6+fee_wd*Inputs!$E$6*(1-wd_red)+fee_fx*Inputs!$D$6-cost_acc-cost_wd*Inputs!$E$6*(1-wd_red)-cost_fx*Inputs!$D$6) -> 191520 | I6: =G6+H6 -> 191520 | J6: =IF(I6=MAX(I$6:I$9),"← best","")
A7: Plus at price 1 | B7: =Inputs!$H$6 -> 2.99 | C7: =Inputs!$I$6 -> 0.15 | D7: =Inputs!$B$6*C7 -> 3600 | E7: =(Inputs!$B$6-D7)*(1-Inputs!$G$6*churn_nonbuyers) -> 19380 | F7: =Inputs!$B$6-D7-E7 -> 1020 | G7: =12*D7*(ic*Inputs!$C$6+B7+fee_fx*Inputs!$D$6-cost_acc-cost_wd*Inputs!$E$6*plus_wdf-cost_fx*Inputs!$D$6-feat_cost) -> 94608 | H7: =12*E7*(ic*Inputs!$C$6+fee_wd*Inputs!$E$6*(1-wd_red)+fee_fx*Inputs!$D$6-cost_acc-cost_wd*Inputs!$E$6*(1-wd_red)-cost_fx*Inputs!$D$6) -> 162792 | I7: =G7+H7 -> 257400 | J7: =IF(I7=MAX(I$6:I$9),"← best","") -> ← best
A8: Plus at price 2 | B8: =Inputs!$J$6 -> 3.99 | C8: =Inputs!$K$6 -> 0.08 | D8: =Inputs!$B$6*C8 -> 1920 | E8: =(Inputs!$B$6-D8)*(1-Inputs!$G$6*churn_nonbuyers) -> 20976 | F8: =Inputs!$B$6-D8-E8 -> 1104 | G8: =12*D8*(ic*Inputs!$C$6+B8+fee_fx*Inputs!$D$6-cost_acc-cost_wd*Inputs!$E$6*plus_wdf-cost_fx*Inputs!$D$6-feat_cost) -> 73497.6 | H8: =12*E8*(ic*Inputs!$C$6+fee_wd*Inputs!$E$6*(1-wd_red)+fee_fx*Inputs!$D$6-cost_acc-cost_wd*Inputs!$E$6*(1-wd_red)-cost_fx*Inputs!$D$6) -> 176198.4 | I8: =G8+H8 -> 249696 | J8: =IF(I8=MAX(I$6:I$9),"← best","")
A9: Plus at price 3 | B9: =Inputs!$L$6 -> 4.99 | C9: =Inputs!$M$6 -> 0.04 | D9: =Inputs!$B$6*C9 -> 960 | E9: =(Inputs!$B$6-D9)*(1-Inputs!$G$6*churn_nonbuyers) -> 21888 | F9: =Inputs!$B$6-D9-E9 -> 1152 | G9: =12*D9*(ic*Inputs!$C$6+B9+fee_fx*Inputs!$D$6-cost_acc-cost_wd*Inputs!$E$6*plus_wdf-cost_fx*Inputs!$D$6-feat_cost) -> 48268.8 | H9: =12*E9*(ic*Inputs!$C$6+fee_wd*Inputs!$E$6*(1-wd_red)+fee_fx*Inputs!$D$6-cost_acc-cost_wd*Inputs!$E$6*(1-wd_red)-cost_fx*Inputs!$D$6) -> 183859.2 | I9: =G9+H9 -> 232128 | J9: =IF(I9=MAX(I$6:I$9),"← best","")
A11: Employees
A12: No plan | C12: 0 | D12: 0 | E12: =Inputs!$B$7*(1-Inputs!$G$7) -> 11640 | F12: =Inputs!$B$7*Inputs!$G$7 -> 360 | G12: 0 | H12: =12*E12*(ic*Inputs!$C$7+fee_wd*Inputs!$E$7*(1-wd_red)+fee_fx*Inputs!$D$7-cost_acc-cost_wd*Inputs!$E$7*(1-wd_red)-cost_fx*Inputs!$D$7) -> 391104 | I12: =G12+H12 -> 391104 | J12: =IF(I12=MAX(I$12:I$15),"← best","")
A13: Plus at price 1 | B13: =Inputs!$H$7 -> 2.99 | C13: =Inputs!$I$7 -> 0.5 | D13: =Inputs!$B$7*C13 -> 6000 | E13: =(Inputs!$B$7-D13)*(1-Inputs!$G$7*churn_nonbuyers) -> 5820 | F13: =Inputs!$B$7-D13-E13 -> 180 | G13: =12*D13*(ic*Inputs!$C$7+B13+fee_fx*Inputs!$D$7-cost_acc-cost_wd*Inputs!$E$7*plus_wdf-cost_fx*Inputs!$D$7-feat_cost) -> 200880 | H13: =12*E13*(ic*Inputs!$C$7+fee_wd*Inputs!$E$7*(1-wd_red)+fee_fx*Inputs!$D$7-cost_acc-cost_wd*Inputs!$E$7*(1-wd_red)-cost_fx*Inputs!$D$7) -> 195552 | I13: =G13+H13 -> 396432 | J13: =IF(I13=MAX(I$12:I$15),"← best","")
A14: Plus at price 2 | B14: =Inputs!$J$7 -> 3.99 | C14: =Inputs!$K$7 -> 0.4 | D14: =Inputs!$B$7*C14 -> 4800 | E14: =(Inputs!$B$7-D14)*(1-Inputs!$G$7*churn_nonbuyers) -> 6984 | F14: =Inputs!$B$7-D14-E14 -> 216 | G14: =12*D14*(ic*Inputs!$C$7+B14+fee_fx*Inputs!$D$7-cost_acc-cost_wd*Inputs!$E$7*plus_wdf-cost_fx*Inputs!$D$7-feat_cost) -> 218304 | H14: =12*E14*(ic*Inputs!$C$7+fee_wd*Inputs!$E$7*(1-wd_red)+fee_fx*Inputs!$D$7-cost_acc-cost_wd*Inputs!$E$7*(1-wd_red)-cost_fx*Inputs!$D$7) -> 234662.4 | I14: =G14+H14 -> 452966.4 | J14: =IF(I14=MAX(I$12:I$15),"← best","") -> ← best
A15: Plus at price 3 | B15: =Inputs!$L$7 -> 4.99 | C15: =Inputs!$M$7 -> 0.2 | D15: =Inputs!$B$7*C15 -> 2400 | E15: =(Inputs!$B$7-D15)*(1-Inputs!$G$7*churn_nonbuyers) -> 9312 | F15: =Inputs!$B$7-D15-E15 -> 288 | G15: =12*D15*(ic*Inputs!$C$7+B15+fee_fx*Inputs!$D$7-cost_acc-cost_wd*Inputs!$E$7*plus_wdf-cost_fx*Inputs!$D$7-feat_cost) -> 137952 | H15: =12*E15*(ic*Inputs!$C$7+fee_wd*Inputs!$E$7*(1-wd_red)+fee_fx*Inputs!$D$7-cost_acc-cost_wd*Inputs!$E$7*(1-wd_red)-cost_fx*Inputs!$D$7) -> 312883.2 | I15: =G15+H15 -> 450835.2 | J15: =IF(I15=MAX(I$12:I$15),"← best","")
A17: Travellers
A18: No plan | C18: 0 | D18: 0 | E18: =Inputs!$B$8*(1-Inputs!$G$8) -> 1200 | F18: =Inputs!$B$8*Inputs!$G$8 -> 2800 | G18: 0 | H18: =12*E18*(ic*Inputs!$C$8+fee_wd*Inputs!$E$8*(1-wd_red)+fee_fx*Inputs!$D$8-cost_acc-cost_wd*Inputs!$E$8*(1-wd_red)-cost_fx*Inputs!$D$8) -> 97920 | I18: =G18+H18 -> 97920 | J18: =IF(I18=MAX(I$18:I$21),"← best","")
A19: Travel at price 1 | B19: =Inputs!$H$8 -> 5.99 | C19: =Inputs!$I$8 -> 0.8 | D19: =Inputs!$B$8*C19 -> 3200 | E19: =(Inputs!$B$8-D19)*(1-Inputs!$G$8*churn_nonbuyers) -> 240 | F19: =Inputs!$B$8-D19-E19 -> 560 | G19: =12*D19*(ic*Inputs!$C$8+B19-cost_acc-cost_wd*Inputs!$E$8-cost_fx*Inputs!$D$8-cost_ins) -> 126336 | H19: =12*E19*(ic*Inputs!$C$8+fee_wd*Inputs!$E$8*(1-wd_red)+fee_fx*Inputs!$D$8-cost_acc-cost_wd*Inputs!$E$8*(1-wd_red)-cost_fx*Inputs!$D$8) -> 19584 | I19: =G19+H19 -> 145920 | J19: =IF(I19=MAX(I$18:I$21),"← best","")
A20: Travel at price 2 | B20: =Inputs!$J$8 -> 6.99 | C20: =Inputs!$K$8 -> 0.7 | D20: =Inputs!$B$8*C20 -> 2800 | E20: =(Inputs!$B$8-D20)*(1-Inputs!$G$8*churn_nonbuyers) -> 360 | F20: =Inputs!$B$8-D20-E20 -> 840 | G20: =12*D20*(ic*Inputs!$C$8+B20-cost_acc-cost_wd*Inputs!$E$8-cost_fx*Inputs!$D$8-cost_ins) -> 144144 | H20: =12*E20*(ic*Inputs!$C$8+fee_wd*Inputs!$E$8*(1-wd_red)+fee_fx*Inputs!$D$8-cost_acc-cost_wd*Inputs!$E$8*(1-wd_red)-cost_fx*Inputs!$D$8) -> 29376 | I20: =G20+H20 -> 173520 | J20: =IF(I20=MAX(I$18:I$21),"← best","") -> ← best
A21: Travel at price 3 | B21: =Inputs!$L$8 -> 8.99 | C21: =Inputs!$M$8 -> 0.3 | D21: =Inputs!$B$8*C21 -> 1200 | E21: =(Inputs!$B$8-D21)*(1-Inputs!$G$8*churn_nonbuyers) -> 840 | F21: =Inputs!$B$8-D21-E21 -> 1960 | G21: =12*D21*(ic*Inputs!$C$8+B21-cost_acc-cost_wd*Inputs!$E$8-cost_fx*Inputs!$D$8-cost_ins) -> 90576 | H21: =12*E21*(ic*Inputs!$C$8+fee_wd*Inputs!$E$8*(1-wd_red)+fee_fx*Inputs!$D$8-cost_acc-cost_wd*Inputs!$E$8*(1-wd_red)-cost_fx*Inputs!$D$8) -> 68544 | I21: =G21+H21 -> 159120 | J21: =IF(I21=MAX(I$18:I$21),"← best","")
A23: Reading: for employees 3.99 beats 4.99 by less than 0.5%, but keeps twice the subscribers (4,800 vs 2,400) — the lower price is the robust choice. For students the plan adds little either way (2.99 is best by 7,700); for travellers 6.99 is clearly best, and 8.99 would win only if more than 37% took it (see Break-even).

Sheet Break-even
A1: Break-even — classic (handout 07, formula 3), breakeven sales change (formula 1), reactive breakeven (handout 08)
A3: Classic break-even against the fixed costs of 700,000
A4: Total contribution per year (recommended) | B4: =reco_total -> 876182.4
A5: Fixed costs | B5: =fixed -> 700000
A6: Profit | B6: =reco_profit -> 176182.4
A7: Customers retained | B7: =Model!E13 -> 37840
A8: Blended contribution per customer per month | B8: =B4/B7/12 -> 1.9295772
A9: Break-even customers at this blend | B9: =fixed/B8/12 -> 30231.148
A10: Contribution may fall by … before a loss | B10: =1-fixed/B4 -> 0.20107959
A11: Break-even in Plus subscribers if everything else stays (extra subscribers needed to close a gap of …) | B11: =MAX(0,-reco_profit) -> 0
A12: … = this many extra employee subscribers at the Plus margin | B12: =B11/12/'Segment economics'!H15 -> 0
A14: Breakeven sales change of a price move: −ΔP / (CM + ΔP) (positive = subscribers that must be won; negative = subscribers that may be lost)
A15: Move | B15: ΔP | C15: CM before | D15: Breakeven sales change | E15: Survey says
A16: Plus for employees: 3.99 → 2.99 | B16: -1 | C16: ='Segment economics'!H15 -> 3.79 | D16: =-B16/(C16+B16) -> 0.35842294 | E16: =Inputs!$I$7/Inputs!$K$7-1 -> 0.25
A17: Plus for employees: 3.99 → 4.99 | B17: 1 | C17: ='Segment economics'!H15 -> 3.79 | D17: =-B17/(C17+B17) -> -0.20876827 | E17: =Inputs!$M$7/Inputs!$K$7-1 -> -0.5
A18: Travel: 6.99 → 5.99 | B18: -1 | C18: ='Segment economics'!M15 -> 4.29 | D18: =-B18/(C18+B18) -> 0.30395137 | E18: =Inputs!$I$8/Inputs!$K$8-1 -> 0.14285714
A19: Travel: 6.99 → 8.99 | B19: 2 | C19: ='Segment economics'!M15 -> 4.29 | D19: =-B19/(C19+B19) -> -0.31796502 | E19: =Inputs!$M$8/Inputs!$K$8-1 -> -0.57142857
A20: Reading: a cut pays only if the survey gain exceeds the breakeven gain; an increase pays only if the survey loss is smaller than the allowed loss. All four moves fail, so 3.99 and 6.99 hold. (The formula ignores that non-buyers fall back to Basic; the full model on Price grid confirms the same ranking.)
A22: Travel at 8.99: the take-up at which 8.99 would beat 6.99 (full model, non-buyers fall back to Basic)
A23: Travellers' contribution per year at 6.99 | B23: =Model!D18 -> 173520
A24: Per traveller per month at 6.99 | B24: =B23/12/Inputs!$B$8 -> 3.615
A25: Contribution per subscriber at 8.99 | B25: =ic*Inputs!$C$8+Inputs!$L$8-cost_acc-cost_wd*Inputs!$E$8-cost_fx*Inputs!$D$8-cost_ins -> 6.29
A26: Contribution per non-buyer (stays on Basic × share who stay) | B26: =(1-Inputs!$G$8)*(ic*Inputs!$C$8+fee_wd*Inputs!$E$8*(1-wd_red)+fee_fx*Inputs!$D$8-cost_acc-cost_wd*Inputs!$E$8*(1-wd_red)-cost_fx*Inputs!$D$8) -> 2.04
A27: Take-up at 8.99 needed to match 6.99 | B27: =(B24-B26)/(B25-B26) -> 0.37058824
A28: Survey take-up at 8.99 | B28: =Inputs!$M$8 -> 0.3
A30: Reactive breakeven (handout 08): if Fluxa undercuts the Travel plan, when does matching pay?
A31: Our price cut to match (ΔP) | B31: 1
A32: Contribution per Travel subscriber (CM) | B32: ='Segment economics'!M15 -> 4.29
A33: Reactive breakeven = ΔP / CM: share of subscribers that must be at risk before matching pays | B33: =B31/B32 -> 0.23310023
A34: Cost of matching per year (all subscribers pay less) | B34: =12*B31*Model!D9 -> 33600
A35: Contribution lost if 10% of Travel subscribers left | B35: =0.1*Model!D9*12*B32 -> 14414.4
A37: Fallback-adjusted breakeven: a lost SUBSCRIBER is not a lost CUSTOMER — most fall back to Basic and keep paying per use
A38: The margin at stake when a subscriber is won or lost is the plan margin minus what the same customer would contribute on Basic (Basic margin × share who stay). This incremental margin goes into the formula −ΔP / (CM + ΔP).
A39: Move | B39: ΔP | C39: Plan CM | D39: Basic CM × share who stay | E39: Incremental CM | F39: Breakeven sales change | G39: Survey says | H39: Verdict
A40: Plus for employees: 3.99 → 2.99 | B40: -1 | C40: ='Segment economics'!H15 -> 3.79 | D40: ='Segment economics'!G15*(1-Inputs!$G$7*churn_nonbuyers) -> 2.716 | E40: =C40-D40 -> 1.074 | F40: =-B40/(E40+B40) -> 13.513514 | G40: =Inputs!$I$7/Inputs!$K$7-1 -> 0.25 | H40: =IF(G40>F40,"pays: move the price","fails: keep the price") -> fails: keep the price
A41: Plus for employees: 3.99 → 4.99 | B41: 1 | C41: ='Segment economics'!H15 -> 3.79 | D41: ='Segment economics'!G15*(1-Inputs!$G$7*churn_nonbuyers) -> 2.716 | E41: =C41-D41 -> 1.074 | F41: =-B41/(E41+B41) -> -0.48216008 | G41: =Inputs!$M$7/Inputs!$K$7-1 -> -0.5 | H41: =IF(G41>F41,"pays: move the price","fails: keep the price") -> fails: keep the price
A42: Travel: 6.99 → 5.99 | B42: -1 | C42: ='Segment economics'!M15 -> 4.29 | D42: ='Segment economics'!K15*(1-Inputs!$G$8*churn_nonbuyers) -> 2.04 | E42: =C42-D42 -> 2.25 | F42: =-B42/(E42+B42) -> 0.8 | G42: =Inputs!$I$8/Inputs!$K$8-1 -> 0.14285714 | H42: =IF(G42>F42,"pays: move the price","fails: keep the price") -> fails: keep the price
A43: Travel: 6.99 → 8.99 | B43: 2 | C43: ='Segment economics'!M15 -> 4.29 | D43: ='Segment economics'!K15*(1-Inputs!$G$8*churn_nonbuyers) -> 2.04 | E43: =C43-D43 -> 2.25 | F43: =-B43/(E43+B43) -> -0.47058824 | G43: =Inputs!$M$8/Inputs!$K$8-1 -> -0.57142857 | H43: =IF(G43>F43,"pays: move the price","fails: keep the price") -> fails: keep the price
A44: Reading: with the fall-back counted, a cut is hopeless (Plus at 2.99 would need +1,351% subscribers; Travel at 5.99 +80%, the survey offers +25% and +14%), and an increase may lose 48% (Plus) or 47% (Travel) of subscribers — the survey loses 50% and 57%. Plus at 4.99 fails by two points only: it is the closest call in the price list, which is why the lower price with twice the subscribers is preferred. The adjusted formula reproduces the full model (Price grid) exactly.
A46: The first price to test: Travel just under the reference value of 8.00
...

Sheet EVE
A1: Economic value estimation (handout 03; Nagle & Müller 2018, Ch. 2): reference value + differentiation value
A2: Reference value = price of the next-best alternative for the same usage. Differentiation value = what our offer adds (+) or lacks (−) against that alternative. Floor of the value-based range = reference value; ceiling = total economic value (handout 07).
A3: Traveller — typical month: 800 card payments, 400 of them in other currencies, 2 withdrawals abroad
A4: Fluxa without Premium: currency fee 1.0% × 400 | B4: =fluxa_fx*Inputs!$D$8 -> 4 | C4: Case fact (competitors).
A5: Fluxa without Premium: 2 withdrawals abroad × 2.00 | B5: =fluxa_wd*Inputs!$E$8 -> 4 | C5: Case fact.
A6: REFERENCE VALUE — next-best alternative for the same usage (Fluxa, no plan) | B6: =B4+B5 -> 8 | C6: Cheapest alternative: own Basic costs 9.00, Fluxa Premium 13.99, a bank 15–19 (rows 20–23).
A7: + Positive differentiation: travel insurance included (price if bought separately) | B7: =ins_sep -> 4 | C7: Case fact: 'about 4 a month'. Counts in full only for travellers who would buy insurance anyway.
A8: − Negative differentiation (nothing quantifiable on the case sheet) | B8: 0 | C8: Assumption: 0. Shared features (euro account, transfers, savings goals) are not differences and are not counted.
A9: TOTAL ECONOMIC VALUE — ceiling of the value-based range | B9: =B6+B7-B8 -> 12 | C9: The most a fully informed traveller would pay.
A10: Floor of the value-based range = reference value | B10: =B6 -> 8 | C10: Handout 07: below the reference value the firm gives away all differentiation value.
A11: 50:50 starting point for a new product (handout 07) | B11: =B6+(B9-B6)/2 -> 10 | C11: Floor plus half of the differentiation value.
A12: Travel price | B12: =pT -> 6.99 | C12: Decision (Inputs).
A13: Customer keeps: economic value − price | B13: =B9-B12 -> 5.01 | C13: Consumer surplus of an informed traveller who wants insurance.
A14: Price minus reference value (negative = priced below the value-based floor) | B14: =B12-B6 -> -1.01 | C14: At 6.99 the plan is 1.01 cheaper than the Fluxa bill before counting the insurance.
A15: Share of differentiation value captured = (price − reference) ÷ (EVC − reference) | B15: =(B12-B6)/(B9-B6) -> -0.2525 | C15: Negative: a penetration price in the sense of handout 07.
A16: Cost floor: variable cost of a Travel subscriber, net of interchange | B16: =cost_acc+cost_wd*Inputs!$E$8+cost_fx*Inputs!$D$8+cost_ins-ic*Inputs!$C$8 -> 2.7 | C16: Lowest price that still covers incremental cost.
A17: Survey: share who would pay the surveyed price just BELOW the reference value (6.99) | B17: =Inputs!$K$8 -> 0.7 | C17: Case fact.
A18: Survey: share who would pay the surveyed price just ABOVE the reference value (8.99) | B18: =Inputs!$M$8 -> 0.3 | C18: Case fact. The cliff 70% → 30% brackets the reference value of 8.00.
A19: Other alternatives, same usage, with separate insurance (for the comparison on the website)
A20: Fluxa without Premium + separate insurance | B20: =B6+ins_sep -> 12
A21: Fluxa Premium 9.99 + 2 withdrawals + insurance | B21: =fluxa_prem+fluxa_wd*Inputs!$E$8+ins_sep -> 17.99
A22: Bank, low: 2.5% × 400 + 2 × 1.00 + package 3.00 + insurance | B22: =bank_fx*Inputs!$D$8+bank_wd_lo*Inputs!$E$8+bank_pkg_lo+ins_sep -> 19
A23: Bank, high: 2.5% × 400 + 2 × 2.00 + package 5.00 + insurance | B23: =bank_fx*Inputs!$D$8+bank_wd_hi*Inputs!$E$8+bank_pkg_hi+ins_sep -> 23
A24: Own Basic account per use (9.00) + insurance | B24: =fee_wd*Inputs!$E$8+fee_fx*Inputs!$D$8+ins_sep -> 13
A26: Reading: the value-based range is 8.00–12.00 and the 50:50 point is 10.00, yet only 30% would pay 8.99. Stated willingness to pay centres on the reference value: 70% accept the surveyed price below 8.00, 30% the one above it. Most travellers therefore perceive little of the 4.00 insurance value. Travel at 6.99 is a deliberate penetration price below the value-based floor: it maximises contribution on the surveyed prices (Price grid), keeps 70% of the most valuable segment, and the conditions of handout 07 hold (high contribution margin; Novčić's 4,000 travellers are too few to provoke Fluxa). The gap between 6.99 and 12.00 is the job of value communication (handout 05), and 7.99 — just under the reference value — is the first price to test (Break-even, row 47).
A28: Young employee — Plus plan: typical month 900 card payments, 50 in other currencies, 2 withdrawals
A29: REFERENCE VALUE — what the employee pays on Basic for the withdrawals Plus includes: 2 × 1.50 | B29: =fee_wd*Inputs!$E$7 -> 3 | C29: Next-best alternative to Plus is staying on Basic.
A30: + Positive differentiation: shared accounts + virtual cards | B30: =Inputs!$L$7-B29 -> 1.99 | C30: Not quantifiable from the case. Proxy: the top fifth of employees would pay 4.99, so for them the features are worth at least this much.
A31: ECONOMIC VALUE for the upper fifth of employees (proxy ceiling) | B31: =B29+B30 -> 4.99 | C31: A survey-based proxy, not a calculated saving.
A32: Plus price | B32: =pE -> 3.99 | C32: Decision (Inputs).
A33: Share of differentiation value captured = (price − reference) ÷ (EVC − reference) | B33: =(B32-B29)/(B31-B29) -> 0.49748744 | C33: 50% = the 50:50 starting point of handout 07.
A34: Survey: share who would pay 2.99 (just below the reference value of 3.00) | B34: =Inputs!$I$7 -> 0.5 | C34: Case fact. Again the median sits at the reference value.
A35: Typical employee's bill on Plus at 2.99 incl. currency fee, vs on Basic | B35: =Inputs!$H$7+fee_fx*Inputs!$D$7 -> 3.74 | C35: 3.74 against 3.75 on Basic: at 2.99 Plus is only a cheaper way to pay for withdrawals (cannibalisation).
A37: Reading: Plus is priced 0.99 ABOVE its reference value, Travel 1.01 BELOW its reference value. The asymmetry follows from what a non-buyer does: an employee who does not buy Plus stays on Basic and still contributes 2.80 a month (97% stay), so a lost subscriber costs little and the firm can ask for a share of the differentiation value. A traveller who does not buy Travel leaves with 70% probability, so the plan is priced to retain.
A39: Student — why there is no monthly fee on the account
A40: Student at a bank: package 3–5 + 1 withdrawal (1–2) + 2.5% × 25, low | B40: =bank_pkg_lo+bank_wd_lo+bank_fx*Inputs!$D$6 -> 4.625
A41: Student at Fluxa: no fee + 1.0% × 25 (+ 2.00 only if the withdrawal is abroad) | B41: =fluxa_fx*Inputs!$D$6 -> 0.25
A42: Student on Novčić Basic: 1 × 1.50 + 1.5% × 25 | B42: =fee_wd*Inputs!$E$6+fee_fx*Inputs!$D$6 -> 1.875
A43: Students who would leave if the account had a monthly fee | B43: =Inputs!$F$6 -> 0.55
A44: Students who would pay 2.99 for Plus | B44: =Inputs!$I$6 -> 0.15
...

Sheet Arbitrage
A1: Do the fences hold? Monthly bill of a typical member of each segment under each offer
A2: A fence works when the customers meant to pay more cannot gain by taking the cheaper offer (handout 04). Here customers choose, so the check is: does each segment pay least on the offer meant for it?
A4: Segment | B4: Basic (per use) | C4: Plus (+ currency fee) | D4: Travel | E4: Cheapest | F4: Comment
A5: Students | B5: =fee_wd*Inputs!$E$6+fee_fx*Inputs!$D$6 -> 1.875 | C5: =pS+fee_fx*Inputs!$D$6+fee_wd*MAX(0,Inputs!$E$6-plus_cap) -> 4.365 | D5: =pT -> 6.99 | E5: =IF(MIN(B5:D5)=B5,"Basic",IF(MIN(B5:D5)=C5,"Plus","Travel")) -> Basic | F5: Basic is cheapest; Plus is bought for its features (15% at 2.99, 8% at 3.99), not to save fees.
A6: Employees | B6: =fee_wd*Inputs!$E$7+fee_fx*Inputs!$D$7 -> 3.75 | C6: =pE+fee_fx*Inputs!$D$7+fee_wd*MAX(0,Inputs!$E$7-plus_cap) -> 4.74 | D6: =pT -> 6.99 | E6: =IF(MIN(B6:D6)=B6,"Basic",IF(MIN(B6:D6)=C6,"Plus","Travel")) -> Basic | F6: Basic is cheapest by 0.99; Plus is bought for shared accounts and virtual cards. At 2.99 Plus would be cheaper than Basic → pure cannibalisation.
A7: Travellers | B7: =fee_wd*Inputs!$E$8+fee_fx*Inputs!$D$8 -> 9 | C7: =pE+fee_fx*Inputs!$D$8+fee_wd*MAX(0,Inputs!$E$8-plus_cap) -> 9.99 | D7: =pT -> 6.99 | E7: =IF(MIN(B7:D7)=B7,"Basic",IF(MIN(B7:D7)=C7,"Plus","Travel")) -> Travel | F7: Travel is cheapest by 2.01 and adds insurance worth about 4.00 — travellers self-select; nobody else gains from Travel.
A9: Ways around the fences and what they cost
A10: Traveller buys Travel only in travel months (monthly, cancel any time) | B10: Pays 6.99 only when abroad; Novčić's variable costs (currency 1.20, withdrawals 2.00, insurance 0.50) also fall in home months, so the loss is the 6.99 − 0.60 account cost in home months. Answer: an annual Travel option at 10 months' price (69.90) rewards commitment (handout 06: discounts for behaviour that saves the seller).
A11: Heavy cash user buys Plus for unlimited withdrawals | B11: Capped: 3 withdrawals included, then 1.50 each. A customer with 6 withdrawals pays 3.99 + 4.50 — the metric tracks cost to serve.
A12: Employee claims a student price (if pS < pE) | B12: Student verification (ISIC / enrolment) — buyer-identification fence. The gain from a separate student price is only about 7,700 a year, so one Plus price is the simpler default.
A13: Student stays on Basic and never withdraws cash | B13: Then the student contributes 0.20 a month (interchange 0.50 + currency fee 0.375 − 0.60 − 0.075): still positive. Basic needs no minimum.

Sheet Sensitivity
A1: Scenario engine — every row recomputes the whole model with its own parameters
A2: Parameter cells that show '=name' follow the Inputs sheet; typed values override for that row only. Add rows by copying one.
A4: Scenario | B4: Basic withdrawals avoided | C4: Plus withdrawal factor | D4: Plus feature cost | E4: Take-up × factor | F4: Per-use churn × factor | G4: Withdrawal cost | H4: Interchange | I4: Withdrawal fee | J4: Currency fee | K4: Plus price S | L4: Plus price E | M4: Travel price | N4: Stud take-up | O4: Stud c/plan | P4: Stud c/basic | Q4: Stud subs | R4: Stud on Basic | S4: Stud contribution | T4: Empl take-up | U4: Empl c/plan | V4: Empl c/basic | W4: Empl subs | X4: Empl on Basic | Y4: Empl contribution | Z4: Trav take-up | AA4: Trav c/plan | AB4: Trav c/basic | AC4: Trav subs | AD4: Trav on Basic | AE4: Trav contribution | AF4: Contribution | AG4: Profit | AH4: Retained
A5: Base case (= Model sheet) | B5: =wd_red -> 0 | C5: =plus_wdf -> 1 | D5: =feat_cost -> 0 | E5: 1 | F5: 1 | G5: =cost_wd -> 1 | H5: =ic -> 0.002 | I5: =fee_wd -> 1.5 | J5: =fee_fx -> 0.015 | K5: =pS -> 3.99 | L5: =pE -> 3.99 | M5: =pT -> 6.99 | N5: =IF($K5="",0,MIN(1,$E5*IF($K5=Inputs!$H$6,Inputs!$I$6,IF($K5=Inputs!$J$6,Inputs!$K$6,IF($K5=Inputs!$L$6,Inputs!$M$6,NA()))))) -> 0.08 | O5: =$H5*Inputs!$C$6+$K5+$J5*Inputs!$D$6-cost_acc-$G5*Inputs!$E$6*$C5-cost_fx*Inputs!$D$6-$D5 -> 3.19 | P5: =$H5*Inputs!$C$6+$I5*Inputs!$E$6*(1-$B5)+$J5*Inputs!$D$6-cost_acc-$G5*Inputs!$E$6*(1-$B5)-cost_fx*Inputs!$D$6 -> 0.7 | Q5: =Inputs!$B$6*N5 -> 1920 | R5: =(Inputs!$B$6-Q5)*(1-MIN(1,Inputs!$G$6*$F5)*churn_nonbuyers) -> 20976 | S5: =12*(Q5*O5+R5*P5) -> 249696 | T5: =IF($L5="",0,MIN(1,$E5*IF($L5=Inputs!$H$7,Inputs!$I$7,IF($L5=Inputs!$J$7,Inputs!$K$7,IF($L5=Inputs!$L$7,Inputs!$M$7,NA()))))) -> 0.4 | U5: =$H5*Inputs!$C$7+$L5+$J5*Inputs!$D$7-cost_acc-$G5*Inputs!$E$7*$C5-cost_fx*Inputs!$D$7-$D5 -> 3.79 | V5: =$H5*Inputs!$C$7+$I5*Inputs!$E$7*(1-$B5)+$J5*Inputs!$D$7-cost_acc-$G5*Inputs!$E$7*(1-$B5)-cost_fx*Inputs!$D$7 -> 2.8 | W5: =Inputs!$B$7*T5 -> 4800 | X5: =(Inputs!$B$7-W5)*(1-MIN(1,Inputs!$G$7*$F5)*churn_nonbuyers) -> 6984 | Y5: =12*(W5*U5+X5*V5) -> 452966.4 | Z5: =IF($M5="",0,MIN(1,$E5*IF($M5=Inputs!$H$8,Inputs!$I$8,IF($M5=Inputs!$J$8,Inputs!$K$8,IF($M5=Inputs!$L$8,Inputs!$M$8,NA()))))) -> 0.7 | AA5: =$H5*Inputs!$C$8+$M5-cost_acc-$G5*Inputs!$E$8-cost_fx*Inputs!$D$8-cost_ins -> 4.29 | AB5: =$H5*Inputs!$C$8+$I5*Inputs!$E$8*(1-$B5)+$J5*Inputs!$D$8-cost_acc-$G5*Inputs!$E$8*(1-$B5)-cost_fx*Inputs!$D$8 -> 6.8 | AC5: =Inputs!$B$8*Z5 -> 2800 | AD5: =(Inputs!$B$8-AC5)*(1-MIN(1,Inputs!$G$8*$F5)*churn_nonbuyers) -> 360 | AE5: =12*(AC5*AA5+AD5*AB5) -> 173520 | AF5: =S5+Y5+AE5 -> 876182.4 | AG5: =AF5-fixed -> 176182.4 | AH5: =Q5+R5+W5+X5+AC5+AD5 -> 37840
